Workbook

Sheet Blocchi25-26
A1: ID | B1: ON SET | C1: GRADO | D1: NUMERO TARGHETTA | E1: COLORE PRESE | F1: ZONA | G1: TRACCIATORE | H1: DATA | I1: DATA SCADENZA | J1: data smontato | K1: viti
A2: 1 | B2: FALSE | C2: Verde | D2: 1 | E2: Blu | F2: dx placca | G2: Andrea | H2: 45908.648 | I2: =IF(C2 = "Smile", H2 + 'Over View'!$B$3, IF(C2 = "Bianco" , H2 + 'Over View'!$B$4, IF(C2 = "Giallo" , H2 + 'Over View'!$B$5, IF(C2 = "Blu" , H2 + 'Over View'!$B$6, IF(C2 = "Verde" , H2 + 'Over View'!$B$7, IF(C2 = "Rosso" , H2 + 'Over View'!$B$8, "Grado Non Inserito") ))))) -> 45929.648 | J2: 45938.456 | K2: T25
A3: 2 | B3: FALSE | C3: Smile | D3: 1 | E3: Verde | F3: dx placca | G3: Fede | H3: 45938.466 | I3: =IF(C3 = "Smile", H3 + 'Over View'!$B$3, IF(C3 = "Bianco" , H3 + 'Over View'!$B$4, IF(C3 = "Giallo" , H3 + 'Over View'!$B$5, IF(C3 = "Blu" , H3 + 'Over View'!$B$6, IF(C3 = "Verde" , H3 + 'Over View'!$B$7, IF(C3 = "Rosso" , H3 + 'Over View'!$B$8, "Grado Non Inserito") ))))) -> 45952.466 | J3: 45938.467 | K3: T25
A4: 3 | B4: FALSE | C4: Blu | D4: 1 | E4: Giallo | F4: dx placca | G4: Andrea | H4: 45908.649 | I4: =IF(C4 = "Smile", H4 + 'Over View'!$B$3, IF(C4 = "Bianco" , H4 + 'Over View'!$B$4, IF(C4 = "Giallo" , H4 + 'Over View'!$B$5, IF(C4 = "Blu" , H4 + 'Over View'!$B$6, IF(C4 = "Verde" , H4 + 'Over View'!$B$7, IF(C4 = "Rosso" , H4 + 'Over View'!$B$8, "Grado Non Inserito") ))))) -> 45938.649 | J4: 45960.672 | K4: T25
A5: 4 | B5: FALSE | C5: Giallo | D5: 1 | E5: Viola | F5: dx placca | G5: Andrea | H5: 45908.65 | I5: =IF(C5 = "Smile", H5 + 'Over View'!$B$3, IF(C5 = "Bianco" , H5 + 'Over View'!$B$4, IF(C5 = "Giallo" , H5 + 'Over View'!$B$5, IF(C5 = "Blu" , H5 + 'Over View'!$B$6, IF(C5 = "Verde" , H5 + 'Over View'!$B$7, IF(C5 = "Rosso" , H5 + 'Over View'!$B$8, "Grado Non Inserito") ))))) -> 45938.65 | J5: 45966.667 | K5: T25
A6: 5 | B6: FALSE | C6: Smile | D6: 2 | E6: Verde | F6: dx verticale | G6: Fede | H6: 45908.65 | I6: =IF(C6 = "Smile", H6 + 'Over View'!$B$3, IF(C6 = "Bianco" , H6 + 'Over View'!$B$4, IF(C6 = "Giallo" , H6 + 'Over View'!$B$5, IF(C6 = "Blu" , H6 + 'Over View'!$B$6, IF(C6 = "Verde" , H6 + 'Over View'!$B$7, IF(C6 = "Rosso" , H6 + 'Over View'!$B$8, "Grado Non Inserito") ))))) -> 45922.65 | J6: 45938.456 | K6: T25
A7: 6 | B7: FALSE | C7: Giallo | D7: 2 | E7: Blu | F7: dx verticale | G7: Andrea | H7: 45908.651 | I7: =IF(C7 = "Smile", H7 + 'Over View'!$B$3, IF(C7 = "Bianco" , H7 + 'Over View'!$B$4, IF(C7 = "Giallo" , H7 + 'Over View'!$B$5, IF(C7 = "Blu" , H7 + 'Over View'!$B$6, IF(C7 = "Verde" , H7 + 'Over View'!$B$7, IF(C7 = "Rosso" , H7 + 'Over View'!$B$8, "Grado Non Inserito") ))))) -> 45938.651 | J7: 45960.672 | K7: T25
A8: 7 | B8: FALSE | C8: Bianco | D8: 1 | E8: Grigio | F8: dx verticale | G8: Fede | H8: 45908.651 | I8: =IF(C8 = "Smile", H8 + 'Over View'!$B$3, IF(C8 = "Bianco" , H8 + 'Over View'!$B$4, IF(C8 = "Giallo" , H8 + 'Over View'!$B$5, IF(C8 = "Blu" , H8 + 'Over View'!$B$6, IF(C8 = "Verde" , H8 + 'Over View'!$B$7, IF(C8 = "Rosso" , H8 + 'Over View'!$B$8, "Grado Non Inserito") ))))) -> 45922.651 | J8: 45938.456 | K8: T25
A9: 8 | B9: FALSE | C9: Blu | D9: 2 | E9: Rosso | F9: dx verticale | G9: Leonardo M | H9: 45908.652 | I9: =IF(C9 = "Smile", H9 + 'Over View'!$B$3, IF(C9 = "Bianco" , H9 + 'Over View'!$B$4, IF(C9 = "Giallo" , H9 + 'Over View'!$B$5, IF(C9 = "Blu" , H9 + 'Over View'!$B$6, IF(C9 = "Verde" , H9 + 'Over View'!$B$7, IF(C9 = "Rosso" , H9 + 'Over View'!$B$8, "Grado Non Inserito") ))))) -> 45938.652 | J9: 45943.441 | K9: T25
A10: 9 | B10: FALSE | C10: Smile | D10: 3 | E10: Nero | F10: dx verticale | G10: Leonardo M | H10: 45908.653 | I10: =IF(C10 = "Smile", H10 + 'Over View'!$B$3, IF(C10 = "Bianco" , H10 + 'Over View'!$B$4, IF(C10 = "Giallo" , H10 + 'Over View'!$B$5, IF(C10 = "Blu" , H10 + 'Over View'!$B$6, IF(C10 = "Verde" , H10 + 'Over View'!$B$7, IF(C10 = "Rosso" , H10 + 'Over View'!$B$8, "Grado Non Inserito") ))))) -> 45922.653 | J10: 45980.507 | K10: T25
A11: 10 | B11: FALSE | C11: Verde | D11: 2 | E11: Blu | F11: dx prua | G11: Andrea | H11: 45908.653 | I11: =IF(C11 = "Smile", H11 + 'Over View'!$B$3, IF(C11 = "Bianco" , H11 + 'Over View'!$B$4, IF(C11 = "Giallo" , H11 + 'Over View'!$B$5, IF(C11 = "Blu" , H11 + 'Over View'!$B$6, IF(C11 = "Verde" , H11 + 'Over View'!$B$7, IF(C11 = "Rosso" , H11 + 'Over View'!$B$8, "Grado Non Inserito") ))))) -> 45929.653 | J11: 45938.456 | K11: T25
A12: 11 | B12: FALSE | C12: Bianco | D12: 2 | E12: Viola | F12: dx prua | G12: Leonardo M | H12: 45908.653 | I12: =IF(C12 = "Smile", H12 + 'Over View'!$B$3, IF(C12 = "Bianco" , H12 + 'Over View'!$B$4, IF(C12 = "Giallo" , H12 + 'Over View'!$B$5, IF(C12 = "Blu" , H12 + 'Over View'!$B$6, IF(C12 = "Verde" , H12 + 'Over View'!$B$7, IF(C12 = "Rosso" , H12 + 'Over View'!$B$8, "Grado Non Inserito") ))))) -> 45922.653 | J12: 45980.507 | K12: T25
A13: 12 | B13: FALSE | C13: Blu | D13: 3 | E13: Verde | F13: dx prua | G13: Leonardo M | H13: 45908.654 | I13: =IF(C13 = "Smile", H13 + 'Over View'!$B$3, IF(C13 = "Bianco" , H13 + 'Over View'!$B$4, IF(C13 = "Giallo" , H13 + 'Over View'!$B$5, IF(C13 = "Blu" , H13 + 'Over View'!$B$6, IF(C13 = "Verde" , H13 + 'Over View'!$B$7, IF(C13 = "Rosso" , H13 + 'Over View'!$B$8, "Grado Non Inserito") ))))) -> 45938.654 | J13: 45980.507 | K13: T25
... A47: 46 | B47: FALSE | C47: Giallo | D47: 3 | E47: Giallo | F47: dx verticale | G47: Leonardo M | H47: 45908.677 | I47: =IF(C47 = "Smile", H47 + 'Over View'!$B$3, IF(C47 = "Bianco" , H47 + 'Over View'!$B$4, IF(C47 = "Giallo" , H47 + 'Over View'!$B$5, IF(C47 = "Blu" , H47 + 'Over View'!$B$6, IF(C47 = "Verde" , H47 + 'Over View'!$B$7, IF(C47 = "Rosso" , H47 + 'Over View'!$B$8, "Grado Non Inserito") ))))) -> 45938.677 | J47: 45966.672 | K47: T25
A48: 47 | B48: FALSE | C48: Blu | D48: 11 | E48: Rosa | F48: sx legg. strapiombo | G48: Leo A | H48: 45912.464 | I48: =IF(C48 = "Smile", H48 + 'Over View'!$B$3, IF(C48 = "Bianco" , H48 + 'Over View'!$B$4, IF(C48 = "Giallo" , H48 + 'Over View'!$B$5, IF(C48 = "Blu" , H48 + 'Over View'!$B$6, IF(C48 = "Verde" , H48 + 'Over View'!$B$7, IF(C48 = "Rosso" , H48 + 'Over View'!$B$8, "Grado Non Inserito") ))))) -> 45942.464 | J48: 46008.519
A49: 48 | B49: FALSE | C49: Smile | D49: 9 | E49: Blu | F49: verticale | G49: Leo A | H49: 45912.464 | I49: =IF(C49 = "Smile", H49 + 'Over View'!$B$3, IF(C49 = "Bianco" , H49 + 'Over View'!$B$4, IF(C49 = "Giallo" , H49 + 'Over View'!$B$5, IF(C49 = "Blu" , H49 + 'Over View'!$B$6, IF(C49 = "Verde" , H49 + 'Over View'!$B$7, IF(C49 = "Rosso" , H49 + 'Over View'!$B$8, "Grado Non Inserito") ))))) -> 45926.464 | J49: 45980.509
A50: 49 | B50: FALSE | C50: Giallo | D50: 15 | E50: Blu | F50: New strapiombo | G50: Dani | H50: 45912.712 | I50: =IF(C50 = "Smile", H50 + 'Over View'!$B$3, IF(C50 = "Bianco" , H50 + 'Over View'!$B$4, IF(C50 = "Giallo" , H50 + 'Over View'!$B$5, IF(C50 = "Blu" , H50 + 'Over View'!$B$6, IF(C50 = "Verde" , H50 + 'Over View'!$B$7, IF(C50 = "Rosso" , H50 + 'Over View'!$B$8, "Grado Non Inserito") ))))) -> 45942.712 | J50: 46031.374 | K50: T25
A51: 50 | B51: FALSE | C51: Smile | E51: Blu | F51: New verticale | G51: Dani | H51: 45912.712 | I51: =IF(C51 = "Smile", H51 + 'Over View'!$B$3, IF(C51 = "Bianco" , H51 + 'Over View'!$B$4, IF(C51 = "Giallo" , H51 + 'Over View'!$B$5, IF(C51 = "Blu" , H51 + 'Over View'!$B$6, IF(C51 = "Verde" , H51 + 'Over View'!$B$7, IF(C51 = "Rosso" , H51 + 'Over View'!$B$8, "Grado Non Inserito") ))))) -> 45926.712 | J51: 46031.374 | K51: T25
A52: 51 | B52: FALSE | C52: Smile | E52: Verde | F52: sx legg. strapiombo | G52: Dani | H52: 45912.712 | I52: =IF(C52 = "Smile", H52 + 'Over View'!$B$3, IF(C52 = "Bianco" , H52 + 'Over View'!$B$4, IF(C52 = "Giallo" , H52 + 'Over View'!$B$5, IF(C52 = "Blu" , H52 + 'Over View'!$B$6, IF(C52 = "Verde" , H52 + 'Over View'!$B$7, IF(C52 = "Rosso" , H52 + 'Over View'!$B$8, "Grado Non Inserito") ))))) -> 45926.712 | J52: 45980.51 | K52: T25
A53: 52 | B53: FALSE | C53: Giallo | D53: 14 | E53: Rosso | F53: sx big strapiombo | G53: Dani | H53: 45912.712 | I53: =IF(C53 = "Smile", H53 + 'Over View'!$B$3, IF(C53 = "Bianco" , H53 + 'Over View'!$B$4, IF(C53 = "Giallo" , H53 + 'Over View'!$B$5, IF(C53 = "Blu" , H53 + 'Over View'!$B$6, IF(C53 = "Verde" , H53 + 'Over View'!$B$7, IF(C53 = "Rosso" , H53 + 'Over View'!$B$8, "Grado Non Inserito") ))))) -> 45942.712 | J53: 46031.374 | K53: T25
A54: 53 | B54: FALSE | C54: Giallo | D54: 12 | E54: Arancione | F54: sx big strapiombo | G54: Dani | H54: 45912.713 | I54: =IF(C54 = "Smile", H54 + 'Over View'!$B$3, IF(C54 = "Bianco" , H54 + 'Over View'!$B$4, IF(C54 = "Giallo" , H54 + 'Over View'!$B$5, IF(C54 = "Blu" , H54 + 'Over View'!$B$6, IF(C54 = "Verde" , H54 + 'Over View'!$B$7, IF(C54 = "Rosso" , H54 + 'Over View'!$B$8, "Grado Non Inserito") ))))) -> 45942.713 | J54: 46031.374 | K54: T25
A55: 54 | B55: FALSE | C55: Bianco | D55: 9 | E55: Rosa | F55: dx placca | G55: Dani | H55: 45912.713 | I55: =IF(C55 = "Smile", H55 + 'Over View'!$B$3, IF(C55 = "Bianco" , H55 + 'Over View'!$B$4, IF(C55 = "Giallo" , H55 + 'Over View'!$B$5, IF(C55 = "Blu" , H55 + 'Over View'!$B$6, IF(C55 = "Verde" , H55 + 'Over View'!$B$7, IF(C55 = "Rosso" , H55 + 'Over View'!$B$8, "Grado Non Inserito") ))))) -> 45926.713 | J55: 45943.421 | K55: T25
A56: 55 | B56: FALSE | C56: Giallo | D56: 13 | E56: Verde | F56: sx big strapiombo | G56: Giulio | H56: 45912.713 | I56: =IF(C56 = "Smile", H56 + 'Over View'!$B$3, IF(C56 = "Bianco" , H56 + 'Over View'!$B$4, IF(C56 = "Giallo" , H56 + 'Over View'!$B$5, IF(C56 = "Blu" , H56 + 'Over View'!$B$6, IF(C56 = "Verde" , H56 + 'Over View'!$B$7, IF(C56 = "Rosso" , H56 + 'Over View'!$B$8, "Grado Non Inserito") ))))) -> 45942.713 | J56: 46031.374 | K56: T25
A57: 56 | B57: FALSE | C57: Blu | D57: 12 | E57: Rosa | F57: dx verticale | G57: Giulio | H57: 45912.714 | I57: =IF(C57 = "Smile", H57 + 'Over View'!$B$3, IF(C57 = "Bianco" , H57 + 'Over View'!$B$4, IF(C57 = "Giallo" , H57 + 'Over View'!$B$5, IF(C57 = "Blu" , H57 + 'Over View'!$B$6, IF(C57 = "Verde" , H57 + 'Over View'!$B$7, IF(C57 = "Rosso" , H57 + 'Over View'!$B$8, "Grado Non Inserito") ))))) -> 45942.714 | J57: 46001.461 | K57: T25
A58: 57 | B58: FALSE | C58: Verde | D58: 6 | E58: Blu | F58: sx big strapiombo | G58: Dani | H58: 45916.374 | I58: =IF(C58 = "Smile", H58 + 'Over View'!$B$3, IF(C58 = "Bianco" , H58 + 'Over View'!$B$4, IF(C58 = "Giallo" , H58 + 'Over View'!$B$5, IF(C58 = "Blu" , H58 + 'Over View'!$B$6, IF(C58 = "Verde" , H58 + 'Over View'!$B$7, IF(C58 = "Rosso" , H58 + 'Over View'!$B$8, "Grado Non Inserito") ))))) -> 45937.374 | J58: 46008.52 | K58: T25
A59: 58 | B59: FALSE | C59: Bianco | D59: 12 | E59: Nero | F59: dx placca | G59: Dani | H59: 45926.909 | I59: =IF(C59 = "Smile", H59 + 'Over View'!$B$3, IF(C59 = "Bianco" , H59 + 'Over View'!$B$4, IF(C59 = "Giallo" , H59 + 'Over View'!$B$5, IF(C59 = "Blu" , H59 + 'Over View'!$B$6, IF(C59 = "Verde" , H59 + 'Over View'!$B$7, IF(C59 = "Rosso" , H59 + 'Over View'!$B$8, "Grado Non Inserito") ))))) -> 45940.909 | J59: 45943.422 | K59: T25
A60: 59 | B60: FALSE | C60: Bianco | D60: 15 | E60: Viola | F60: dx verticale | G60: Dani | H60: 45926.909 | I60: =IF(C60 = "Smile", H60 + 'Over View'!$B$3, IF(C60 = "Bianco" , H60 + 'Over View'!$B$4, IF(C60 = "Giallo" , H60 + 'Over View'!$B$5, IF(C60 = "Blu" , H60 + 'Over View'!$B$6, IF(C60 = "Verde" , H60 + 'Over View'!$B$7, IF(C60 = "Rosso" , H60 + 'Over View'!$B$8, "Grado Non Inserito") ))))) -> 45940.909 | J60: 46031.374 | K60: T25
A61: 60 | B61: FALSE | C61: Blu | D61: 13 | E61: Giallo | F61: dx prua | G61: Dani | H61: 45926.91 | I61: =IF(C61 = "Smile", H61 + 'Over View'!$B$3, IF(C61 = "Bianco" , H61 + 'Over View'!$B$4, IF(C61 = "Giallo" , H61 + 'Over View'!$B$5, IF(C61 = "Blu" , H61 + 'Over View'!$B$6, IF(C61 = "Verde" , H61 + 'Over View'!$B$7, IF(C61 = "Rosso" , H61 + 'Over View'!$B$8, "Grado Non Inserito") ))))) -> 45956.91 | J61: 46001.461 | K61: T25
A62: 61 | B62: FALSE | C62: Giallo | D62: 16 | E62: Nero | F62: verticale | G62: Leo A | H62: 45926.91 | I62: =IF(C62 = "Smile", H62 + 'Over View'!$B$3, IF(C62 = "Bianco" , H62 + 'Over View'!$B$4, IF(C62 = "Giallo" , H62 + 'Over View'!$B$5, IF(C62 = "Blu" , H62 + 'Over View'!$B$6, IF(C62 = "Verde" , H62 + 'Over View'!$B$7, IF(C62 = "Rosso" , H62 + 'Over View'!$B$8, "Grado Non Inserito") ))))) -> 45956.91 | J62: 45966.674 | K62: T25
A63: 62 | B63: FALSE | C63: Bianco | D63: 13 | E63: Giallo | F63: verticale | G63: Dani | H63: 45926.91 | I63: =IF(C63 = "Smile", H63 + 'Over View'!$B$3, IF(C63 = "Bianco" , H63 + 'Over View'!$B$4, IF(C63 = "Giallo" , H63 + 'Over View'!$B$5, IF(C63 = "Blu" , H63 + 'Over View'!$B$6, IF(C63 = "Verde" , H63 + 'Over View'!$B$7, IF(C63 = "Rosso" , H63 + 'Over View'!$B$8, "Grado Non Inserito") ))))) -> 45940.91 | J63: 46031.374 | K63: T25
A64: 63 | B64: FALSE | C64: Rosso | D64: 5 | E64: Viola | F64: sx big strapiombo | G64: Dani | H64: 45926.911 | I64: =IF(C64 = "Smile", H64 + 'Over View'!$B$3, IF(C64 = "Bianco" , H64 + 'Over View'!$B$4, IF(C64 = "Giallo" , H64 + 'Over View'!$B$5, IF(C64 = "Blu" , H64 + 'Over View'!$B$6, IF(C64 = "Verde" , H64 + 'Over View'!$B$7, IF(C64 = "Rosso" , H64 + 'Over View'!$B$8, "Grado Non Inserito") ))))) -> 45947.911 | J64: 46031.374 | K64: T25
... A81: 80 | B81: FALSE | C81: Bianco | D81: 16 | E81: Arancione | F81: New verticale | G81: Dani | H81: 45946.668 | I81: =IF(C81 = "Smile", H81 + 'Over View'!$B$3, IF(C81 = "Bianco" , H81 + 'Over View'!$B$4, IF(C81 = "Giallo" , H81 + 'Over View'!$B$5, IF(C81 = "Blu" , H81 + 'Over View'!$B$6, IF(C81 = "Verde" , H81 + 'Over View'!$B$7, IF(C81 = "Rosso" , H81 + 'Over View'!$B$8, "Grado Non Inserito") ))))) -> 45960.668 | J81: 46031.375 | K81: T25
A82: 81 | B82: FALSE | C82: Bianco | E82: Verde | F82: sx legg. strapiombo | G82: Dani | H82: 45946.668 | I82: =IF(C82 = "Smile", H82 + 'Over View'!$B$3, IF(C82 = "Bianco" , H82 + 'Over View'!$B$4, IF(C82 = "Giallo" , H82 + 'Over View'!$B$5, IF(C82 = "Blu" , H82 + 'Over View'!$B$6, IF(C82 = "Verde" , H82 + 'Over View'!$B$7, IF(C82 = "Rosso" , H82 + 'Over View'!$B$8, "Grado Non Inserito") ))))) -> 45960.668 | J82: 46031.375 | K82: T25
A83: 82 | B83: FALSE | C83: Verde | E83: Verde | F83: verticale | G83: Dani | H83: 45946.669 | I83: =IF(C83 = "Smile", H83 + 'Over View'!$B$3, IF(C83 = "Bianco" , H83 + 'Over View'!$B$4, IF(C83 = "Giallo" , H83 + 'Over View'!$B$5, IF(C83 = "Blu" , H83 + 'Over View'!$B$6, IF(C83 = "Verde" , H83 + 'Over View'!$B$7, IF(C83 = "Rosso" , H83 + 'Over View'!$B$8, "Grado Non Inserito") ))))) -> 45967.669 | J83: 46031.375 | K83: T25
A84: 83 | B84: FALSE | C84: Bianco | E84: Nero | F84: dx verticale | G84: Dani | H84: 45946.669 | I84: =IF(C84 = "Smile", H84 + 'Over View'!$B$3, IF(C84 = "Bianco" , H84 + 'Over View'!$B$4, IF(C84 = "Giallo" , H84 + 'Over View'!$B$5, IF(C84 = "Blu" , H84 + 'Over View'!$B$6, IF(C84 = "Verde" , H84 + 'Over View'!$B$7, IF(C84 = "Rosso" , H84 + 'Over View'!$B$8, "Grado Non Inserito") ))))) -> 45960.669 | J84: 46031.375 | K84: T25
A85: 84 | B85: FALSE | C85: Smile | D85: 4 | E85: Grigio | F85: verticale | G85: Andrea | H85: 45950.548 | I85: =IF(C85 = "Smile", H85 + 'Over View'!$B$3, IF(C85 = "Bianco" , H85 + 'Over View'!$B$4, IF(C85 = "Giallo" , H85 + 'Over View'!$B$5, IF(C85 = "Blu" , H85 + 'Over View'!$B$6, IF(C85 = "Verde" , H85 + 'Over View'!$B$7, IF(C85 = "Rosso" , H85 + 'Over View'!$B$8, "Grado Non Inserito") ))))) -> 45964.548 | J85: 46031.375 | K85: T25
A86: 85 | B86: FALSE | C86: Bianco | D86: 3 | E86: Verde | F86: dx prua | G86: Andrea | H86: 45950.549 | I86: =IF(C86 = "Smile", H86 + 'Over View'!$B$3, IF(C86 = "Bianco" , H86 + 'Over View'!$B$4, IF(C86 = "Giallo" , H86 + 'Over View'!$B$5, IF(C86 = "Blu" , H86 + 'Over View'!$B$6, IF(C86 = "Verde" , H86 + 'Over View'!$B$7, IF(C86 = "Rosso" , H86 + 'Over View'!$B$8, "Grado Non Inserito") ))))) -> 45964.549 | J86: 46008.52 | K86: T25
A87: 86 | B87: FALSE | C87: Bianco | D87: 7 | E87: Nero | F87: New placca | G87: Dani | H87: 45952.472 | I87: =IF(C87 = "Smile", H87 + 'Over View'!$B$3, IF(C87 = "Bianco" , H87 + 'Over View'!$B$4, IF(C87 = "Giallo" , H87 + 'Over View'!$B$5, IF(C87 = "Blu" , H87 + 'Over View'!$B$6, IF(C87 = "Verde" , H87 + 'Over View'!$B$7, IF(C87 = "Rosso" , H87 + 'Over View'!$B$8, "Grado Non Inserito") ))))) -> 45966.472 | J87: 46031.375 | K87: T25
A88: 87 | B88: FALSE | C88: Blu | D88: 17 | E88: Viola | F88: New verticale | G88: Giulio | H88: 45952.472 | I88: =IF(C88 = "Smile", H88 + 'Over View'!$B$3, IF(C88 = "Bianco" , H88 + 'Over View'!$B$4, IF(C88 = "Giallo" , H88 + 'Over View'!$B$5, IF(C88 = "Blu" , H88 + 'Over View'!$B$6, IF(C88 = "Verde" , H88 + 'Over View'!$B$7, IF(C88 = "Rosso" , H88 + 'Over View'!$B$8, "Grado Non Inserito") ))))) -> 45982.472 | J88: 46031.375 | K88: T25
A89: 88 | B89: FALSE | C89: Verde | D89: 4 | E89: Viola | F89: New strapiombo | G89: Giulio | H89: 45952.472 | I89: =IF(C89 = "Smile", H89 + 'Over View'!$B$3, IF(C89 = "Bianco" , H89 + 'Over View'!$B$4, IF(C89 = "Giallo" , H89 + 'Over View'!$B$5, IF(C89 = "Blu" , H89 + 'Over View'!$B$6, IF(C89 = "Verde" , H89 + 'Over View'!$B$7, IF(C89 = "Rosso" , H89 + 'Over View'!$B$8, "Grado Non Inserito") ))))) -> 45973.472 | J89: 46031.375 | K89: T25
...

Sheet Over View
A1: Date di scadenza | D1: Totali boulder On set | F1: Obiettivo
A2: Grado | B2: Durata (giorni) | D2: Totale | E2: =COUNTIF('Blocchi25-26'!B:B, TRUE()) -> 68 | F2: =Sum(F3:F8) -> 65
A3: Smile | B3: 14 | D3: Smile | E3: =COUNTIFS('Blocchi25-26'!C:C, "Smile",'Blocchi25-26'!B:B, TRUE()) -> 10 | F3: 10
A4: Bianco | B4: 14 | D4: Bianco | E4: =COUNTIFS('Blocchi25-26'!C:C, "Bianco",'Blocchi25-26'!B:B, TRUE()) -> 16 | F4: 15
A5: Giallo | B5: 30 | D5: Giallo | E5: =COUNTIFS('Blocchi25-26'!C:C, "GIallo",'Blocchi25-26'!B:B, TRUE()) -> 15 | F5: 15
A6: Blu | B6: 30 | D6: Blu | E6: =COUNTIFS('Blocchi25-26'!C:C, "Blu",'Blocchi25-26'!B:B, TRUE()) -> 15 | F6: 15
A7: Verde | B7: 21 | D7: Verde | E7: =COUNTIFS('Blocchi25-26'!C:C, "Verde",'Blocchi25-26'!B:B, TRUE()) -> 7 | F7: 5
A8: Rosso | B8: 21 | D8: Rosso | E8: =COUNTIFS('Blocchi25-26'!C:C, "Rosso",'Blocchi25-26'!B:B, TRUE()) -> 5 | F8: 5
A10: Blocchi in ...
A11: Old sala | B11: New Sala
A12: =E2-B12 -> 49 | B12: =COUNTIFS('Blocchi25-26'!F:F,"New*", 'Blocchi25-26'!B:B, TRUE()) -> 19

Sheet Blocchi24-25
A1: ID | B1: Grado | C1: Numero targhetta | D1: Colore Prese | E1: Zona | F1: Tracciatore | G1: Data | H1: Data Scadenza | I1: One set | J1: Viti | K1: Quando off set | L1: Colonna filtro
A2: 1 | B2: Blu | C2: 13 | G2: 45670 | H2: =IF(B2 = "Smile", G2 + 'Over View'!$B$3, IF(B2 = "Bianco" , G2 + 'Over View'!$B$4, IF(B2 = "Giallo" , G2 + 'Over View'!$B$5, IF(B2 = "Blu" , G2 + 'Over View'!$B$6, IF(B2 = "Verde" , G2 + 'Over View'!$B$7, IF(B2 = "Rosso" , G2 + 'Over View'!$B$8, "Grado Non Inserito") ))))) -> 45700 | I2: FALSE | K2: 45681 | L2: =IF(I2 = TRUE(), "on set", "off set") -> off set
A3: 2 | B3: Giallo | C3: 18 | G3: 45670 | H3: =IF(B3 = "Smile", G3 + 'Over View'!$B$3, IF(B3 = "Bianco" , G3 + 'Over View'!$B$4, IF(B3 = "Giallo" , G3 + 'Over View'!$B$5, IF(B3 = "Blu" , G3 + 'Over View'!$B$6, IF(B3 = "Verde" , G3 + 'Over View'!$B$7, IF(B3 = "Rosso" , G3 + 'Over View'!$B$8, "Grado Non Inserito") ))))) -> 45700 | I3: FALSE | K3: 45681 | L3: =IF(I3 = TRUE(), "on set", "off set") -> off set
A4: 3 | B4: Giallo | C4: 10 | G4: 45670 | H4: =IF(B4 = "Smile", G4 + 'Over View'!$B$3, IF(B4 = "Bianco" , G4 + 'Over View'!$B$4, IF(B4 = "Giallo" , G4 + 'Over View'!$B$5, IF(B4 = "Blu" , G4 + 'Over View'!$B$6, IF(B4 = "Verde" , G4 + 'Over View'!$B$7, IF(B4 = "Rosso" , G4 + 'Over View'!$B$8, "Grado Non Inserito") ))))) -> 45700 | I4: FALSE | K4: 45681 | L4: =IF(I4 = TRUE(), "on set", "off set") -> off set
A5: 4 | B5: Blu | C5: 15 | G5: 45670 | H5: =IF(B5 = "Smile", G5 + 'Over View'!$B$3, IF(B5 = "Bianco" , G5 + 'Over View'!$B$4, IF(B5 = "Giallo" , G5 + 'Over View'!$B$5, IF(B5 = "Blu" , G5 + 'Over View'!$B$6, IF(B5 = "Verde" , G5 + 'Over View'!$B$7, IF(B5 = "Rosso" , G5 + 'Over View'!$B$8, "Grado Non Inserito") ))))) -> 45700 | I5: FALSE | K5: 45681 | L5: =IF(I5 = TRUE(), "on set", "off set") -> off set
A6: 5 | B6: Bianco | C6: 6 | G6: 45670 | H6: =IF(B6 = "Smile", G6 + 'Over View'!$B$3, IF(B6 = "Bianco" , G6 + 'Over View'!$B$4, IF(B6 = "Giallo" , G6 + 'Over View'!$B$5, IF(B6 = "Blu" , G6 + 'Over View'!$B$6, IF(B6 = "Verde" , G6 + 'Over View'!$B$7, IF(B6 = "Rosso" , G6 + 'Over View'!$B$8, "Grado Non Inserito") ))))) -> 45684 | I6: FALSE | K6: 45681 | L6: =IF(I6 = TRUE(), "on set", "off set") -> off set
A7: 6 | B7: Verde | C7: 13 | G7: 45670 | H7: =IF(B7 = "Smile", G7 + 'Over View'!$B$3, IF(B7 = "Bianco" , G7 + 'Over View'!$B$4, IF(B7 = "Giallo" , G7 + 'Over View'!$B$5, IF(B7 = "Blu" , G7 + 'Over View'!$B$6, IF(B7 = "Verde" , G7 + 'Over View'!$B$7, IF(B7 = "Rosso" , G7 + 'Over View'!$B$8, "Grado Non Inserito") ))))) -> 45691 | I7: FALSE | K7: 45681 | L7: =IF(I7 = TRUE(), "on set", "off set") -> off set
A8: 7 | B8: Bianco | C8: 19 | G8: 45670 | H8: =IF(B8 = "Smile", G8 + 'Over View'!$B$3, IF(B8 = "Bianco" , G8 + 'Over View'!$B$4, IF(B8 = "Giallo" , G8 + 'Over View'!$B$5, IF(B8 = "Blu" , G8 + 'Over View'!$B$6, IF(B8 = "Verde" , G8 + 'Over View'!$B$7, IF(B8 = "Rosso" , G8 + 'Over View'!$B$8, "Grado Non Inserito") ))))) -> 45684 | I8: FALSE | K8: 45681 | L8: =IF(I8 = TRUE(), "on set", "off set") -> off set
A9: 8 | B9: Smile | C9: 8 | G9: 45670 | H9: =IF(B9 = "Smile", G9 + 'Over View'!$B$3, IF(B9 = "Bianco" , G9 + 'Over View'!$B$4, IF(B9 = "Giallo" , G9 + 'Over View'!$B$5, IF(B9 = "Blu" , G9 + 'Over View'!$B$6, IF(B9 = "Verde" , G9 + 'Over View'!$B$7, IF(B9 = "Rosso" , G9 + 'Over View'!$B$8, "Grado Non Inserito") ))))) -> 45684 | I9: FALSE | K9: 45681 | L9: =IF(I9 = TRUE(), "on set", "off set") -> off set
A10: 9 | B10: Blu | C10: 17 | G10: 45670 | H10: =IF(B10 = "Smile", G10 + 'Over View'!$B$3, IF(B10 = "Bianco" , G10 + 'Over View'!$B$4, IF(B10 = "Giallo" , G10 + 'Over View'!$B$5, IF(B10 = "Blu" , G10 + 'Over View'!$B$6, IF(B10 = "Verde" , G10 + 'Over View'!$B$7, IF(B10 = "Rosso" , G10 + 'Over View'!$B$8, "Grado Non Inserito") ))))) -> 45700 | I10: FALSE | K10: 45681 | L10: =IF(I10 = TRUE(), "on set", "off set") -> off set
A11: 10 | B11: Verde | C11: 14 | G11: 45670 | H11: =IF(B11 = "Smile", G11 + 'Over View'!$B$3, IF(B11 = "Bianco" , G11 + 'Over View'!$B$4, IF(B11 = "Giallo" , G11 + 'Over View'!$B$5, IF(B11 = "Blu" , G11 + 'Over View'!$B$6, IF(B11 = "Verde" , G11 + 'Over View'!$B$7, IF(B11 = "Rosso" , G11 + 'Over View'!$B$8, "Grado Non Inserito") ))))) -> 45691 | I11: FALSE | K11: 45681 | L11: =IF(I11 = TRUE(), "on set", "off set") -> off set
A12: 11 | B12: Bianco | C12: 16 | G12: 45670 | H12: =IF(B12 = "Smile", G12 + 'Over View'!$B$3, IF(B12 = "Bianco" , G12 + 'Over View'!$B$4, IF(B12 = "Giallo" , G12 + 'Over View'!$B$5, IF(B12 = "Blu" , G12 + 'Over View'!$B$6, IF(B12 = "Verde" , G12 + 'Over View'!$B$7, IF(B12 = "Rosso" , G12 + 'Over View'!$B$8, "Grado Non Inserito") ))))) -> 45684 | I12: FALSE | K12: 45681 | L12: =IF(I12 = TRUE(), "on set", "off set") -> off set
A13: 12 | B13: Smile | C13: 12 | G13: 45670 | H13: =IF(B13 = "Smile", G13 + 'Over View'!$B$3, IF(B13 = "Bianco" , G13 + 'Over View'!$B$4, IF(B13 = "Giallo" , G13 + 'Over View'!$B$5, IF(B13 = "Blu" , G13 + 'Over View'!$B$6, IF(B13 = "Verde" , G13 + 'Over View'!$B$7, IF(B13 = "Rosso" , G13 + 'Over View'!$B$8, "Grado Non Inserito") ))))) -> 45684 | I13: FALSE | K13: 45681 | L13: =IF(I13 = TRUE(), "on set", "off set") -> off set
... A16: 15 | B16: Giallo | C16: 15 | G16: 45670 | H16: =IF(B16 = "Smile", G16 + 'Over View'!$B$3, IF(B16 = "Bianco" , G16 + 'Over View'!$B$4, IF(B16 = "Giallo" , G16 + 'Over View'!$B$5, IF(B16 = "Blu" , G16 + 'Over View'!$B$6, IF(B16 = "Verde" , G16 + 'Over View'!$B$7, IF(B16 = "Rosso" , G16 + 'Over View'!$B$8, "Grado Non Inserito") ))))) -> 45700 | I16: FALSE | K16: 45681 | L16: =IF(I16 = TRUE(), "on set", "off set") -> off set
A17: 16 | B17: Giallo | C17: 7 | E17: dx placca | F17: Leonardo M | G17: 45670 | H17: =IF(B17 = "Smile", G17 + 'Over View'!$B$3, IF(B17 = "Bianco" , G17 + 'Over View'!$B$4, IF(B17 = "Giallo" , G17 + 'Over View'!$B$5, IF(B17 = "Blu" , G17 + 'Over View'!$B$6, IF(B17 = "Verde" , G17 + 'Over View'!$B$7, IF(B17 = "Rosso" , G17 + 'Over View'!$B$8, "Grado Non Inserito") ))))) -> 45700 | I17: FALSE | K17: 45681 | L17: =IF(I17 = TRUE(), "on set", "off set") -> off set
A18: 17 | B18: Bianco | C18: 8 | E18: dx placca | F18: Leonardo M | G18: 45670 | H18: =IF(B18 = "Smile", G18 + 'Over View'!$B$3, IF(B18 = "Bianco" , G18 + 'Over View'!$B$4, IF(B18 = "Giallo" , G18 + 'Over View'!$B$5, IF(B18 = "Blu" , G18 + 'Over View'!$B$6, IF(B18 = "Verde" , G18 + 'Over View'!$B$7, IF(B18 = "Rosso" , G18 + 'Over View'!$B$8, "Grado Non Inserito") ))))) -> 45684 | I18: FALSE | K18: 45681 | L18: =IF(I18 = TRUE(), "on set", "off set") -> off set
A19: 18 | B19: Giallo | C19: 8 | G19: 45670 | H19: =IF(B19 = "Smile", G19 + 'Over View'!$B$3, IF(B19 = "Bianco" , G19 + 'Over View'!$B$4, IF(B19 = "Giallo" , G19 + 'Over View'!$B$5, IF(B19 = "Blu" , G19 + 'Over View'!$B$6, IF(B19 = "Verde" , G19 + 'Over View'!$B$7, IF(B19 = "Rosso" , G19 + 'Over View'!$B$8, "Grado Non Inserito") ))))) -> 45700 | I19: FALSE | K19: 45681 | L19: =IF(I19 = TRUE(), "on set", "off set") -> off set
A20: 19 | B20: Smile | C20: 10 | G20: 45670 | H20: =IF(B20 = "Smile", G20 + 'Over View'!$B$3, IF(B20 = "Bianco" , G20 + 'Over View'!$B$4, IF(B20 = "Giallo" , G20 + 'Over View'!$B$5, IF(B20 = "Blu" , G20 + 'Over View'!$B$6, IF(B20 = "Verde" , G20 + 'Over View'!$B$7, IF(B20 = "Rosso" , G20 + 'Over View'!$B$8, "Grado Non Inserito") ))))) -> 45684 | I20: FALSE | K20: 45681 | L20: =IF(I20 = TRUE(), "on set", "off set") -> off set
A21: 20 | B21: Bianco | C21: 5 | G21: 45670 | H21: =IF(B21 = "Smile", G21 + 'Over View'!$B$3, IF(B21 = "Bianco" , G21 + 'Over View'!$B$4, IF(B21 = "Giallo" , G21 + 'Over View'!$B$5, IF(B21 = "Blu" , G21 + 'Over View'!$B$6, IF(B21 = "Verde" , G21 + 'Over View'!$B$7, IF(B21 = "Rosso" , G21 + 'Over View'!$B$8, "Grado Non Inserito") ))))) -> 45684 | I21: FALSE | K21: 45681 | L21: =IF(I21 = TRUE(), "on set", "off set") -> off set
A22: 21 | B22: Smile | C22: 1 | G22: 45670 | H22: =IF(B22 = "Smile", G22 + 'Over View'!$B$3, IF(B22 = "Bianco" , G22 + 'Over View'!$B$4, IF(B22 = "Giallo" , G22 + 'Over View'!$B$5, IF(B22 = "Blu" , G22 + 'Over View'!$B$6, IF(B22 = "Verde" , G22 + 'Over View'!$B$7, IF(B22 = "Rosso" , G22 + 'Over View'!$B$8, "Grado Non Inserito") ))))) -> 45684 | I22: FALSE | K22: 45681 | L22: =IF(I22 = TRUE(), "on set", "off set") -> off set
A23: 22 | B23: Giallo | C23: 5 | G23: 45670 | H23: =IF(B23 = "Smile", G23 + 'Over View'!$B$3, IF(B23 = "Bianco" , G23 + 'Over View'!$B$4, IF(B23 = "Giallo" , G23 + 'Over View'!$B$5, IF(B23 = "Blu" , G23 + 'Over View'!$B$6, IF(B23 = "Verde" , G23 + 'Over View'!$B$7, IF(B23 = "Rosso" , G23 + 'Over View'!$B$8, "Grado Non Inserito") ))))) -> 45700 | I23: FALSE | K23: 45681 | L23: =IF(I23 = TRUE(), "on set", "off set") -> off set
A24: 23 | B24: Smile | C24: 3 | G24: 45670 | H24: =IF(B24 = "Smile", G24 + 'Over View'!$B$3, IF(B24 = "Bianco" , G24 + 'Over View'!$B$4, IF(B24 = "Giallo" , G24 + 'Over View'!$B$5, IF(B24 = "Blu" , G24 + 'Over View'!$B$6, IF(B24 = "Verde" , G24 + 'Over View'!$B$7, IF(B24 = "Rosso" , G24 + 'Over View'!$B$8, "Grado Non Inserito") ))))) -> 45684 | I24: FALSE | K24: 45681 | L24: =IF(I24 = TRUE(), "on set", "off set") -> off set
A25: 24 | B25: Bianco | C25: 14 | G25: 45670 | H25: =IF(B25 = "Smile", G25 + 'Over View'!$B$3, IF(B25 = "Bianco" , G25 + 'Over View'!$B$4, IF(B25 = "Giallo" , G25 + 'Over View'!$B$5, IF(B25 = "Blu" , G25 + 'Over View'!$B$6, IF(B25 = "Verde" , G25 + 'Over View'!$B$7, IF(B25 = "Rosso" , G25 + 'Over View'!$B$8, "Grado Non Inserito") ))))) -> 45684 | I25: FALSE | K25: 45681 | L25: =IF(I25 = TRUE(), "on set", "off set") -> off set
A26: 25 | B26: Bianco | C26: 11 | G26: 45670 | H26: =IF(B26 = "Smile", G26 + 'Over View'!$B$3, IF(B26 = "Bianco" , G26 + 'Over View'!$B$4, IF(B26 = "Giallo" , G26 + 'Over View'!$B$5, IF(B26 = "Blu" , G26 + 'Over View'!$B$6, IF(B26 = "Verde" , G26 + 'Over View'!$B$7, IF(B26 = "Rosso" , G26 + 'Over View'!$B$8, "Grado Non Inserito") ))))) -> 45684 | I26: FALSE | K26: 45681 | L26: =IF(I26 = TRUE(), "on set", "off set") -> off set
A27: 26 | B27: Bianco | C27: 3 | G27: 45670 | H27: =IF(B27 = "Smile", G27 + 'Over View'!$B$3, IF(B27 = "Bianco" , G27 + 'Over View'!$B$4, IF(B27 = "Giallo" , G27 + 'Over View'!$B$5, IF(B27 = "Blu" , G27 + 'Over View'!$B$6, IF(B27 = "Verde" , G27 + 'Over View'!$B$7, IF(B27 = "Rosso" , G27 + 'Over View'!$B$8, "Grado Non Inserito") ))))) -> 45684 | I27: FALSE | K27: 45681 | L27: =IF(I27 = TRUE(), "on set", "off set") -> off set
A28: 27 | B28: Blu | C28: 9 | G28: 45670 | H28: =IF(B28 = "Smile", G28 + 'Over View'!$B$3, IF(B28 = "Bianco" , G28 + 'Over View'!$B$4, IF(B28 = "Giallo" , G28 + 'Over View'!$B$5, IF(B28 = "Blu" , G28 + 'Over View'!$B$6, IF(B28 = "Verde" , G28 + 'Over View'!$B$7, IF(B28 = "Rosso" , G28 + 'Over View'!$B$8, "Grado Non Inserito") ))))) -> 45700 | I28: FALSE | K28: 45681 | L28: =IF(I28 = TRUE(), "on set", "off set") -> off set
A29: 28 | B29: Giallo | C29: 20 | G29: 45670 | H29: =IF(B29 = "Smile", G29 + 'Over View'!$B$3, IF(B29 = "Bianco" , G29 + 'Over View'!$B$4, IF(B29 = "Giallo" , G29 + 'Over View'!$B$5, IF(B29 = "Blu" , G29 + 'Over View'!$B$6, IF(B29 = "Verde" , G29 + 'Over View'!$B$7, IF(B29 = "Rosso" , G29 + 'Over View'!$B$8, "Grado Non Inserito") ))))) -> 45700 | I29: FALSE | K29: 45681 | L29: =IF(I29 = TRUE(), "on set", "off set") -> off set
A30: 29 | B30: Verde | C30: 5 | G30: 45670 | H30: =IF(B30 = "Smile", G30 + 'Over View'!$B$3, IF(B30 = "Bianco" , G30 + 'Over View'!$B$4, IF(B30 = "Giallo" , G30 + 'Over View'!$B$5, IF(B30 = "Blu" , G30 + 'Over View'!$B$6, IF(B30 = "Verde" , G30 + 'Over View'!$B$7, IF(B30 = "Rosso" , G30 + 'Over View'!$B$8, "Grado Non Inserito") ))))) -> 45691 | I30: FALSE | K30: 45681 | L30: =IF(I30 = TRUE(), "on set", "off set") -> off set
... A32: 31 | B32: Smile | C32: 7 | G32: 45670 | H32: =IF(B32 = "Smile", G32 + 'Over View'!$B$3, IF(B32 = "Bianco" , G32 + 'Over View'!$B$4, IF(B32 = "Giallo" , G32 + 'Over View'!$B$5, IF(B32 = "Blu" , G32 + 'Over View'!$B$6, IF(B32 = "Verde" , G32 + 'Over View'!$B$7, IF(B32 = "Rosso" , G32 + 'Over View'!$B$8, "Grado Non Inserito") ))))) -> 45684 | I32: FALSE | K32: 45681 | L32: =IF(I32 = TRUE(), "on set", "off set") -> off set
A33: 32 | B33: Bianco | C33: 14 | F33: Leonardo M | G33: 45670 | H33: =IF(B33 = "Smile", G33 + 'Over View'!$B$3, IF(B33 = "Bianco" , G33 + 'Over View'!$B$4, IF(B33 = "Giallo" , G33 + 'Over View'!$B$5, IF(B33 = "Blu" , G33 + 'Over View'!$B$6, IF(B33 = "Verde" , G33 + 'Over View'!$B$7, IF(B33 = "Rosso" , G33 + 'Over View'!$B$8, "Grado Non Inserito") ))))) -> 45684 | I33: FALSE | K33: 45681 | L33: =IF(I33 = TRUE(), "on set", "off set") -> off set
A34: 33 | B34: Giallo | C34: 9 | G34: 45670 | H34: =IF(B34 = "Smile", G34 + 'Over View'!$B$3, IF(B34 = "Bianco" , G34 + 'Over View'!$B$4, IF(B34 = "Giallo" , G34 + 'Over View'!$B$5, IF(B34 = "Blu" , G34 + 'Over View'!$B$6, IF(B34 = "Verde" , G34 + 'Over View'!$B$7, IF(B34 = "Rosso" , G34 + 'Over View'!$B$8, "Grado Non Inserito") ))))) -> 45700 | I34: FALSE | K34: 45681 | L34: =IF(I34 = TRUE(), "on set", "off set") -> off set
A35: 34 | B35: Blu | C35: 4 | G35: 45670 | H35: =IF(B35 = "Smile", G35 + 'Over View'!$B$3, IF(B35 = "Bianco" , G35 + 'Over View'!$B$4, IF(B35 = "Giallo" , G35 + 'Over View'!$B$5, IF(B35 = "Blu" , G35 + 'Over View'!$B$6, IF(B35 = "Verde" , G35 + 'Over View'!$B$7, IF(B35 = "Rosso" , G35 + 'Over View'!$B$8, "Grado Non Inserito") ))))) -> 45700 | I35: FALSE | K35: 45681 | L35: =IF(I35 = TRUE(), "on set", "off set") -> off set
A36: 35 | B36: Bianco | C36: 6 | E36: verticale | F36: Leonardo M | G36: 45670 | H36: =IF(B36 = "Smile", G36 + 'Over View'!$B$3, IF(B36 = "Bianco" , G36 + 'Over View'!$B$4, IF(B36 = "Giallo" , G36 + 'Over View'!$B$5, IF(B36 = "Blu" , G36 + 'Over View'!$B$6, IF(B36 = "Verde" , G36 + 'Over View'!$B$7, IF(B36 = "Rosso" , G36 + 'Over View'!$B$8, "Grado Non Inserito") ))))) -> 45684 | I36: FALSE | K36: 45681 | L36: =IF(I36 = TRUE(), "on set", "off set") -> off set
A37: 36 | B37: Giallo | C37: 13 | E37: verticale | F37: Leonardo M | G37: 45670 | H37: =IF(B37 = "Smile", G37 + 'Over View'!$B$3, IF(B37 = "Bianco" , G37 + 'Over View'!$B$4, IF(B37 = "Giallo" , G37 + 'Over View'!$B$5, IF(B37 = "Blu" , G37 + 'Over View'!$B$6, IF(B37 = "Verde" , G37 + 'Over View'!$B$7, IF(B37 = "Rosso" , G37 + 'Over View'!$B$8, "Grado Non Inserito") ))))) -> 45700 | I37: FALSE | K37: 45681 | L37: =IF(I37 = TRUE(), "on set", "off set") -> off set
A38: 37 | B38: Smile | C38: 2 | G38: 45670 | H38: =IF(B38 = "Smile", G38 + 'Over View'!$B$3, IF(B38 = "Bianco" , G38 + 'Over View'!$B$4, IF(B38 = "Giallo" , G38 + 'Over View'!$B$5, IF(B38 = "Blu" , G38 + 'Over View'!$B$6, IF(B38 = "Verde" , G38 + 'Over View'!$B$7, IF(B38 = "Rosso" , G38 + 'Over View'!$B$8, "Grado Non Inserito") ))))) -> 45684 | I38: FALSE | K38: 45681 | L38: =IF(I38 = TRUE(), "on set", "off set") -> off set
A39: 38 | B39: Smile | C39: 6 | E39: verticale | F39: Leonardo M | G39: 45670 | H39: =IF(B39 = "Smile", G39 + 'Over View'!$B$3, IF(B39 = "Bianco" , G39 + 'Over View'!$B$4, IF(B39 = "Giallo" , G39 + 'Over View'!$B$5, IF(B39 = "Blu" , G39 + 'Over View'!$B$6, IF(B39 = "Verde" , G39 + 'Over View'!$B$7, IF(B39 = "Rosso" , G39 + 'Over View'!$B$8, "Grado Non Inserito") ))))) -> 45684 | I39: FALSE | K39: 45681 | L39: =IF(I39 = TRUE(), "on set", "off set") -> off set
A40: 39 | B40: Giallo | C40: 3 | G40: 45670 | H40: =IF(B40 = "Smile", G40 + 'Over View'!$B$3, IF(B40 = "Bianco" , G40 + 'Over View'!$B$4, IF(B40 = "Giallo" , G40 + 'Over View'!$B$5, IF(B40 = "Blu" , G40 + 'Over View'!$B$6, IF(B40 = "Verde" , G40 + 'Over View'!$B$7, IF(B40 = "Rosso" , G40 + 'Over View'!$B$8, "Grado Non Inserito") ))))) -> 45700 | I40: FALSE | K40: 45681 | L40: =IF(I40 = TRUE(), "on set", "off set") -> off set
A41: 40 | B41: Bianco | C41: 2 | G41: 45670 | H41: =IF(B41 = "Smile", G41 + 'Over View'!$B$3, IF(B41 = "Bianco" , G41 + 'Over View'!$B$4, IF(B41 = "Giallo" , G41 + 'Over View'!$B$5, IF(B41 = "Blu" , G41 + 'Over View'!$B$6, IF(B41 = "Verde" , G41 + 'Over View'!$B$7, IF(B41 = "Rosso" , G41 + 'Over View'!$B$8, "Grado Non Inserito") ))))) -> 45684 | I41: FALSE | K41: 45681 | L41: =IF(I41 = TRUE(), "on set", "off set") -> off set
A42: 41 | B42: Blu | C42: 9 | G42: 45670 | H42: =IF(B42 = "Smile", G42 + 'Over View'!$B$3, IF(B42 = "Bianco" , G42 + 'Over View'!$B$4, IF(B42 = "Giallo" , G42 + 'Over View'!$B$5, IF(B42 = "Blu" , G42 + 'Over View'!$B$6, IF(B42 = "Verde" , G42 + 'Over View'!$B$7, IF(B42 = "Rosso" , G42 + 'Over View'!$B$8, "Grado Non Inserito") ))))) -> 45700 | I42: FALSE | K42: 45681 | L42: =IF(I42 = TRUE(), "on set", "off set") -> off set
A43: 42 | B43: Verde | C43: 2 | G43: 45670 | H43: =IF(B43 = "Smile", G43 + 'Over View'!$B$3, IF(B43 = "Bianco" , G43 + 'Over View'!$B$4, IF(B43 = "Giallo" , G43 + 'Over View'!$B$5, IF(B43 = "Blu" , G43 + 'Over View'!$B$6, IF(B43 = "Verde" , G43 + 'Over View'!$B$7, IF(B43 = "Rosso" , G43 + 'Over View'!$B$8, "Grado Non Inserito") ))))) -> 45691 | I43: FALSE | K43: 45681 | L43: =IF(I43 = TRUE(), "on set", "off set") -> off set
...
